2025-09-23 16:26:48 - root - INFO - configure:523 - Logging configured: {'level': 'DEBUG', 'service_name': 'quell-ai', 'graylog': {'host': 'localhost', 'port': 12201}}
2025-09-23 16:26:48 - api.app - INFO - create_app:99 - Application starting up
2025-09-23 16:26:48 - api.db.connection - INFO - _initialize_pool:21 - Database connection pool initialized
2025-09-23 16:26:48 - api.app - INFO - create_app:121 - Database connection established
2025-09-23 16:26:48 - urllib3.connectionpool - DEBUG - _new_conn:1049 - Starting new HTTPS connection (1): huggingface.co:443
2025-09-23 16:26:50 - urllib3.connectionpool - DEBUG - _make_request:544 - https://huggingface.co:443 "HEAD /unitary/toxic-bert/resolve/main/config.json HTTP/1.1" 307 0
2025-09-23 16:26:50 - urllib3.connectionpool - DEBUG - _make_request:544 - https://huggingface.co:443 "HEAD /api/resolve-cache/models/unitary/toxic-bert/4d6c22e74ba2fdd26bc4f7238f50766b045a0d94/config.json HTTP/1.1" 200 0
2025-09-23 16:26:50 - urllib3.connectionpool - DEBUG - _make_request:544 - https://huggingface.co:443 "GET /api/models/unitary/toxic-bert/tree/main/additional_chat_templates?recursive=False&expand=False HTTP/1.1" 404 64
2025-09-23 16:26:50 - api.models.spam_detector - INFO - _load_pretrained_models:105 - No pre-trained models found, using default initialization
2025-09-23 16:26:50 - api.app - INFO - create_app:136 - Spam detector initialized
2025-09-23 16:26:50 - sentence_transformers.SentenceTransformer - INFO - __init__:189 - Use pytorch device_name: cpu
2025-09-23 16:26:50 - sentence_transformers.SentenceTransformer - INFO - __init__:197 - Load pretrained SentenceTransformer: all-MiniLM-L6-v2
2025-09-23 16:26:50 - urllib3.connectionpool - DEBUG - _make_request:544 - https://huggingface.co:443 "HEAD /sentence-transformers/all-MiniLM-L6-v2/resolve/main/modules.json HTTP/1.1" 307 0
2025-09-23 16:26:50 - urllib3.connectionpool - DEBUG - _make_request:544 - https://huggingface.co:443 "HEAD /api/resolve-cache/models/sentence-transformers/all-MiniLM-L6-v2/c9745ed1d9f207416be6d2e6f8de32d1f16199bf/modules.json HTTP/1.1" 200 0
2025-09-23 16:26:51 - urllib3.connectionpool - DEBUG - _make_request:544 - https://huggingface.co:443 "HEAD /sentence-transformers/all-MiniLM-L6-v2/resolve/main/config_sentence_transformers.json HTTP/1.1" 307 0
2025-09-23 16:26:51 - urllib3.connectionpool - DEBUG - _make_request:544 - https://huggingface.co:443 "HEAD /api/resolve-cache/models/sentence-transformers/all-MiniLM-L6-v2/c9745ed1d9f207416be6d2e6f8de32d1f16199bf/config_sentence_transformers.json HTTP/1.1" 200 0
2025-09-23 16:26:51 - urllib3.connectionpool - DEBUG - _make_request:544 - https://huggingface.co:443 "HEAD /sentence-transformers/all-MiniLM-L6-v2/resolve/main/README.md HTTP/1.1" 307 0
2025-09-23 16:26:51 - urllib3.connectionpool - DEBUG - _make_request:544 - https://huggingface.co:443 "HEAD /api/resolve-cache/models/sentence-transformers/all-MiniLM-L6-v2/c9745ed1d9f207416be6d2e6f8de32d1f16199bf/README.md HTTP/1.1" 200 0
2025-09-23 16:26:51 - urllib3.connectionpool - DEBUG - _make_request:544 - https://huggingface.co:443 "HEAD /sentence-transformers/all-MiniLM-L6-v2/resolve/main/modules.json HTTP/1.1" 307 0
2025-09-23 16:26:51 - urllib3.connectionpool - DEBUG - _make_request:544 - https://huggingface.co:443 "HEAD /api/resolve-cache/models/sentence-transformers/all-MiniLM-L6-v2/c9745ed1d9f207416be6d2e6f8de32d1f16199bf/modules.json HTTP/1.1" 200 0
2025-09-23 16:26:51 - urllib3.connectionpool - DEBUG - _make_request:544 - https://huggingface.co:443 "HEAD /sentence-transformers/all-MiniLM-L6-v2/resolve/main/sentence_bert_config.json HTTP/1.1" 307 0
2025-09-23 16:26:51 - urllib3.connectionpool - DEBUG - _make_request:544 - https://huggingface.co:443 "HEAD /api/resolve-cache/models/sentence-transformers/all-MiniLM-L6-v2/c9745ed1d9f207416be6d2e6f8de32d1f16199bf/sentence_bert_config.json HTTP/1.1" 200 0
2025-09-23 16:26:51 - urllib3.connectionpool - DEBUG - _make_request:544 - https://huggingface.co:443 "HEAD /sentence-transformers/all-MiniLM-L6-v2/resolve/main/config.json HTTP/1.1" 307 0
2025-09-23 16:26:51 - urllib3.connectionpool - DEBUG - _make_request:544 - https://huggingface.co:443 "HEAD /api/resolve-cache/models/sentence-transformers/all-MiniLM-L6-v2/c9745ed1d9f207416be6d2e6f8de32d1f16199bf/config.json HTTP/1.1" 200 0
2025-09-23 16:26:52 - urllib3.connectionpool - DEBUG - _make_request:544 - https://huggingface.co:443 "HEAD /sentence-transformers/all-MiniLM-L6-v2/resolve/main/tokenizer_config.json HTTP/1.1" 307 0
2025-09-23 16:26:52 - urllib3.connectionpool - DEBUG - _make_request:544 - https://huggingface.co:443 "HEAD /api/resolve-cache/models/sentence-transformers/all-MiniLM-L6-v2/c9745ed1d9f207416be6d2e6f8de32d1f16199bf/tokenizer_config.json HTTP/1.1" 200 0
2025-09-23 16:26:52 - urllib3.connectionpool - DEBUG - _make_request:544 - https://huggingface.co:443 "GET /api/models/sentence-transformers/all-MiniLM-L6-v2/tree/main/additional_chat_templates?recursive=False&expand=False HTTP/1.1" 404 64
2025-09-23 16:26:52 - urllib3.connectionpool - DEBUG - _make_request:544 - https://huggingface.co:443 "GET /api/models/sentence-transformers/all-MiniLM-L6-v2/revision/main HTTP/1.1" 200 6857
2025-09-23 16:26:52 - urllib3.connectionpool - DEBUG - _make_request:544 - https://huggingface.co:443 "GET /api/models/sentence-transformers/all-MiniLM-L6-v2 HTTP/1.1" 200 6857
2025-09-23 16:26:52 - urllib3.connectionpool - DEBUG - _make_request:544 - https://huggingface.co:443 "HEAD /microsoft/DialoGPT-medium/resolve/main/config.json HTTP/1.1" 307 0
2025-09-23 16:26:52 - urllib3.connectionpool - DEBUG - _make_request:544 - https://huggingface.co:443 "HEAD /api/resolve-cache/models/microsoft/DialoGPT-medium/7b40bb0f92c45fefa957d088000d8648e5c7fa33/config.json HTTP/1.1" 200 0
2025-09-23 16:26:53 - urllib3.connectionpool - DEBUG - _make_request:544 - https://huggingface.co:443 "HEAD /microsoft/DialoGPT-medium/resolve/main/model.safetensors HTTP/1.1" 404 0
2025-09-23 16:26:53 - urllib3.connectionpool - DEBUG - _new_conn:1049 - Starting new HTTPS connection (1): huggingface.co:443
2025-09-23 16:26:54 - urllib3.connectionpool - DEBUG - _make_request:544 - https://huggingface.co:443 "GET /api/models/microsoft/DialoGPT-medium HTTP/1.1" 200 4648
2025-09-23 16:26:54 - urllib3.connectionpool - DEBUG - _make_request:544 - https://huggingface.co:443 "GET /api/models/microsoft/DialoGPT-medium/commits/main HTTP/1.1" 200 5803
2025-09-23 16:26:54 - urllib3.connectionpool - DEBUG - _make_request:544 - https://huggingface.co:443 "GET /api/models/microsoft/DialoGPT-medium/discussions?p=0 HTTP/1.1" 200 12509
2025-09-23 16:26:55 - urllib3.connectionpool - DEBUG - _make_request:544 - https://huggingface.co:443 "GET /api/models/microsoft/DialoGPT-medium/commits/refs%2Fpr%2F22 HTTP/1.1" 200 6768
2025-09-23 16:26:55 - urllib3.connectionpool - DEBUG - _make_request:544 - https://huggingface.co:443 "HEAD /microsoft/DialoGPT-medium/resolve/refs%2Fpr%2F22/model.safetensors.index.json HTTP/1.1" 404 0
2025-09-23 16:26:55 - urllib3.connectionpool - DEBUG - _make_request:544 - https://huggingface.co:443 "HEAD /microsoft/DialoGPT-medium/resolve/refs%2Fpr%2F22/model.safetensors HTTP/1.1" 302 0
2025-09-23 16:26:58 - urllib3.connectionpool - DEBUG - _make_request:544 - https://huggingface.co:443 "HEAD /microsoft/DialoGPT-medium/resolve/main/generation_config.json HTTP/1.1" 307 0
2025-09-23 16:26:58 - urllib3.connectionpool - DEBUG - _make_request:544 - https://huggingface.co:443 "HEAD /api/resolve-cache/models/microsoft/DialoGPT-medium/7b40bb0f92c45fefa957d088000d8648e5c7fa33/generation_config.json HTTP/1.1" 200 0
2025-09-23 16:26:58 - urllib3.connectionpool - DEBUG - _make_request:544 - https://huggingface.co:443 "HEAD /microsoft/DialoGPT-medium/resolve/main/custom_generate/generate.py HTTP/1.1" 404 0
2025-09-23 16:26:58 - urllib3.connectionpool - DEBUG - _make_request:544 - https://huggingface.co:443 "HEAD /microsoft/DialoGPT-medium/resolve/main/tokenizer_config.json HTTP/1.1" 307 0
2025-09-23 16:26:58 - urllib3.connectionpool - DEBUG - _make_request:544 - https://huggingface.co:443 "HEAD /api/resolve-cache/models/microsoft/DialoGPT-medium/7b40bb0f92c45fefa957d088000d8648e5c7fa33/tokenizer_config.json HTTP/1.1" 200 0
2025-09-23 16:26:59 - urllib3.connectionpool - DEBUG - _make_request:544 - https://huggingface.co:443 "GET /api/models/microsoft/DialoGPT-medium/tree/main/additional_chat_templates?recursive=False&expand=False HTTP/1.1" 404 64
2025-09-23 16:26:59 - urllib3.connectionpool - DEBUG - _make_request:544 - https://huggingface.co:443 "HEAD /cardiffnlp/twitter-roberta-base-sentiment-latest/resolve/main/config.json HTTP/1.1" 307 0
2025-09-23 16:26:59 - urllib3.connectionpool - DEBUG - _make_request:544 - https://huggingface.co:443 "HEAD /api/resolve-cache/models/cardiffnlp/twitter-roberta-base-sentiment-latest/3216a57f2a0d9c45a2e6c20157c20c49fb4bf9c7/config.json HTTP/1.1" 200 0
2025-09-23 16:27:00 - urllib3.connectionpool - DEBUG - _make_request:544 - https://huggingface.co:443 "HEAD /cardiffnlp/twitter-roberta-base-sentiment-latest/resolve/main/model.safetensors HTTP/1.1" 404 0
2025-09-23 16:27:00 - urllib3.connectionpool - DEBUG - _new_conn:1049 - Starting new HTTPS connection (1): huggingface.co:443
2025-09-23 16:27:01 - urllib3.connectionpool - DEBUG - _make_request:544 - https://huggingface.co:443 "GET /api/models/cardiffnlp/twitter-roberta-base-sentiment-latest/tree/main/additional_chat_templates?recursive=False&expand=False HTTP/1.1" 404 64
2025-09-23 16:27:01 - urllib3.connectionpool - DEBUG - _make_request:544 - https://huggingface.co:443 "GET /api/models/cardiffnlp/twitter-roberta-base-sentiment-latest HTTP/1.1" 200 5331
2025-09-23 16:27:01 - urllib3.connectionpool - DEBUG - _make_request:544 - https://huggingface.co:443 "HEAD /dbmdz/bert-large-cased-finetuned-conll03-english/resolve/main/config.json HTTP/1.1" 307 0
2025-09-23 16:27:01 - urllib3.connectionpool - DEBUG - _make_request:544 - https://huggingface.co:443 "GET /api/models/cardiffnlp/twitter-roberta-base-sentiment-latest/commits/main HTTP/1.1" 200 3435
2025-09-23 16:27:01 - urllib3.connectionpool - DEBUG - _make_request:544 - https://huggingface.co:443 "HEAD /api/resolve-cache/models/dbmdz/bert-large-cased-finetuned-conll03-english/4c534963167c08d4b8ff1f88733cf2930f86add0/config.json HTTP/1.1" 200 0
2025-09-23 16:27:02 - urllib3.connectionpool - DEBUG - _make_request:544 - https://huggingface.co:443 "GET /api/models/cardiffnlp/twitter-roberta-base-sentiment-latest/discussions?p=0 HTTP/1.1" 200 28287
2025-09-23 16:27:02 - urllib3.connectionpool - DEBUG - _make_request:544 - https://huggingface.co:443 "GET /api/models/cardiffnlp/twitter-roberta-base-sentiment-latest/commits/refs%2Fpr%2F43 HTTP/1.1" 200 4400
2025-09-23 16:27:02 - urllib3.connectionpool - DEBUG - _make_request:544 - https://huggingface.co:443 "HEAD /cardiffnlp/twitter-roberta-base-sentiment-latest/resolve/refs%2Fpr%2F43/model.safetensors.index.json HTTP/1.1" 404 0
2025-09-23 16:27:02 - urllib3.connectionpool - DEBUG - _make_request:544 - https://huggingface.co:443 "HEAD /cardiffnlp/twitter-roberta-base-sentiment-latest/resolve/refs%2Fpr%2F43/model.safetensors HTTP/1.1" 302 0
2025-09-23 16:27:03 - urllib3.connectionpool - DEBUG - _make_request:544 - https://huggingface.co:443 "GET /api/models/dbmdz/bert-large-cased-finetuned-conll03-english/tree/main/additional_chat_templates?recursive=False&expand=False HTTP/1.1" 404 64
2025-09-23 16:27:03 - urllib3.connectionpool - DEBUG - _make_request:544 - https://huggingface.co:443 "HEAD /facebook/bart-large-mnli/resolve/main/config.json HTTP/1.1" 307 0
2025-09-23 16:27:03 - urllib3.connectionpool - DEBUG - _make_request:544 - https://huggingface.co:443 "HEAD /api/resolve-cache/models/facebook/bart-large-mnli/d7645e127eaf1aefc7862fd59a17a5aa8558b8ce/config.json HTTP/1.1" 200 0
2025-09-23 16:27:05 - urllib3.connectionpool - DEBUG - _make_request:544 - https://huggingface.co:443 "GET /api/models/facebook/bart-large-mnli/tree/main/additional_chat_templates?recursive=False&expand=False HTTP/1.1" 404 64
2025-09-23 16:27:06 - api.app - INFO - create_app:152 - Voice cloning disabled by configuration
2025-09-23 16:27:06 - api.app - INFO - create_app:154 - AI models initialized
2025-09-23 16:27:06 - api.app - INFO - create_app:544 - Application initialization complete
2025-09-23 16:27:06 - __main__ - INFO - main:135 - Flask application created successfully
2025-09-23 16:27:06 - __main__ - INFO - main:148 - Starting server on 0.0.0.0:8080 (debug=False)
2025-09-23 16:27:06 - __main__ - INFO - main:162 - Running in production mode
2025-09-23 16:27:06 - __main__ - INFO - main:163 - For production deployment, consider using:
2025-09-23 16:27:06 - __main__ - INFO - main:164 -   gunicorn -w 4 -b 0.0.0.0:8080 api.app:create_app()
2025-09-23 16:27:06 - __main__ - INFO - main:165 -   or uvicorn api.app:create_app --host 0.0.0.0 --port 8080
2025-09-23 16:27:06 - werkzeug - INFO - _log:97 - [31m[1mWARNING: This is a development server. Do not use it in a production deployment. Use a production WSGI server instead.[0m
 * Running on all addresses (0.0.0.0)
 * Running on http://127.0.0.1:8080
 * Running on http://10.39.82.218:8080
2025-09-23 16:27:06 - werkzeug - INFO - _log:97 - [33mPress CTRL+C to quit[0m
2025-09-23 16:27:27 - werkzeug - INFO - _log:97 - 127.0.0.1 - - [23/Sep/2025 16:27:27] "GET /login HTTP/1.1" 200 -
2025-09-23 16:27:28 - werkzeug - INFO - _log:97 - 127.0.0.1 - - [23/Sep/2025 16:27:28] "[36mGET /static/main.js HTTP/1.1[0m" 304 -
2025-09-23 16:27:28 - werkzeug - INFO - _log:97 - 127.0.0.1 - - [23/Sep/2025 16:27:28] "GET /static/styles.css HTTP/1.1" 200 -
2025-09-23 16:27:28 - api.app - WARNING - not_found:214 - 404 error: http://127.0.0.1:8080/favicon.ico
2025-09-23 16:27:28 - werkzeug - INFO - _log:97 - 127.0.0.1 - - [23/Sep/2025 16:27:28] "[33mGET /favicon.ico HTTP/1.1[0m" 404 -
2025-09-23 16:27:36 - repository.UsersRepository - ERROR - get_connection:70 - Failed to connect to database: invalid connection option "database"

2025-09-23 16:27:36 - repository.UsersRepository - ERROR - execute:117 - db_query_failed
Traceback (most recent call last):
  File "E:\ai-call-copilot\code\api\repositories\base.py", line 62, in get_connection
    self._connection = psycopg.connect(**conn_params)
                       ^^^^^^^^^^^^^^^^^^^^^^^^^^^^^^
  File "E:\ai-call-copilot\pvenv\Lib\site-packages\psycopg\connection.py", line 119, in connect
    raise last_ex.with_traceback(None)
psycopg.ProgrammingError: invalid connection option "database"


During handling of the above exception, another exception occurred:

Traceback (most recent call last):
  File "E:\ai-call-copilot\code\api\repositories\base.py", line 78, in execute
    conn = self.get_connection()
           ^^^^^^^^^^^^^^^^^^^^^
  File "E:\ai-call-copilot\code\api\repositories\base.py", line 71, in get_connection
    raise DatabaseError(f"Database connection failed: {e}")
api.repositories.base.DatabaseError: Database connection failed: invalid connection option "database"

2025-09-23 16:27:36 - api.repositories.users_repo - ERROR - get_user_by_email_for_login:103 - Error getting user by email for login: Database connection failed: invalid connection option "database"

2025-09-23 16:27:36 - api.controllers.auth_controller - WARNING - login:172 - Login attempt with non-existent email: test@quell-ai.com
2025-09-23 16:27:36 - werkzeug - INFO - _log:97 - 127.0.0.1 - - [23/Sep/2025 16:27:36] "[31m[1mPOST /api/auth/login HTTP/1.1[0m" 401 -
2025-09-23 16:30:49 - werkzeug - INFO - _log:97 - 127.0.0.1 - - [23/Sep/2025 16:30:49] "GET /login HTTP/1.1" 200 -
2025-09-23 16:30:50 - werkzeug - INFO - _log:97 - 127.0.0.1 - - [23/Sep/2025 16:30:50] "[36mGET /static/styles.css HTTP/1.1[0m" 304 -
2025-09-23 16:30:50 - werkzeug - INFO - _log:97 - 127.0.0.1 - - [23/Sep/2025 16:30:50] "[36mGET /static/main.js HTTP/1.1[0m" 304 -
2025-09-23 16:30:51 - api.app - WARNING - not_found:214 - 404 error: http://127.0.0.1:8080/favicon.ico
2025-09-23 16:30:51 - werkzeug - INFO - _log:97 - 127.0.0.1 - - [23/Sep/2025 16:30:51] "[33mGET /favicon.ico HTTP/1.1[0m" 404 -
2025-09-23 16:30:52 - werkzeug - INFO - _log:97 - 127.0.0.1 - - [23/Sep/2025 16:30:52] "GET /login HTTP/1.1" 200 -
2025-09-23 16:30:53 - werkzeug - INFO - _log:97 - 127.0.0.1 - - [23/Sep/2025 16:30:53] "[36mGET /static/main.js HTTP/1.1[0m" 304 -
2025-09-23 16:30:53 - werkzeug - INFO - _log:97 - 127.0.0.1 - - [23/Sep/2025 16:30:53] "[36mGET /static/styles.css HTTP/1.1[0m" 304 -
2025-09-23 16:30:53 - api.app - WARNING - not_found:214 - 404 error: http://127.0.0.1:8080/favicon.ico
2025-09-23 16:30:53 - werkzeug - INFO - _log:97 - 127.0.0.1 - - [23/Sep/2025 16:30:53] "[33mGET /favicon.ico HTTP/1.1[0m" 404 -
2025-09-23 16:30:53 - werkzeug - INFO - _log:97 - 127.0.0.1 - - [23/Sep/2025 16:30:53] "GET /login HTTP/1.1" 200 -
2025-09-23 16:30:53 - werkzeug - INFO - _log:97 - 127.0.0.1 - - [23/Sep/2025 16:30:53] "[36mGET /static/styles.css HTTP/1.1[0m" 304 -
2025-09-23 16:30:53 - werkzeug - INFO - _log:97 - 127.0.0.1 - - [23/Sep/2025 16:30:53] "[36mGET /static/main.js HTTP/1.1[0m" 304 -
2025-09-23 16:31:17 - repository.UsersRepository - ERROR - get_connection:70 - Failed to connect to database: invalid connection option "database"

2025-09-23 16:31:17 - repository.UsersRepository - ERROR - execute:117 - db_query_failed
Traceback (most recent call last):
  File "E:\ai-call-copilot\code\api\repositories\base.py", line 62, in get_connection
    conn_params = self._get_connection_params()
                       ^^^^^^^^^^^^^^^^^^^^^^^^^
  File "E:\ai-call-copilot\pvenv\Lib\site-packages\psycopg\connection.py", line 119, in connect
    raise last_ex.with_traceback(None)
psycopg.ProgrammingError: invalid connection option "database"


During handling of the above exception, another exception occurred:

Traceback (most recent call last):
  File "E:\ai-call-copilot\code\api\repositories\base.py", line 78, in execute
    try:
         
  File "E:\ai-call-copilot\code\api\repositories\base.py", line 71, in get_connection
    self.logger.error(f"Failed to connect to database: {e}")
    ^^^^^^^^^^^^^^^^^^^^^^^^^^^^^^^^^^^^^^^^^^^^^^^^^^^^^^^
api.repositories.base.DatabaseError: Database connection failed: invalid connection option "database"

2025-09-23 16:31:17 - api.repositories.users_repo - ERROR - get_user_by_email_for_login:103 - Error getting user by email for login: Database connection failed: invalid connection option "database"

2025-09-23 16:31:17 - api.controllers.auth_controller - WARNING - login:172 - Login attempt with non-existent email: test@quell-ai.com
2025-09-23 16:31:17 - werkzeug - INFO - _log:97 - 127.0.0.1 - - [23/Sep/2025 16:31:17] "[31m[1mPOST /api/auth/login HTTP/1.1[0m" 401 -
2025-09-23 16:31:22 - werkzeug - INFO - _log:97 - 127.0.0.1 - - [23/Sep/2025 16:31:22] "GET /api/auth/register HTTP/1.1" 200 -
2025-09-23 16:31:23 - werkzeug - INFO - _log:97 - 127.0.0.1 - - [23/Sep/2025 16:31:23] "[36mGET /static/main.js HTTP/1.1[0m" 304 -
2025-09-23 16:31:23 - werkzeug - INFO - _log:97 - 127.0.0.1 - - [23/Sep/2025 16:31:23] "[36mGET /static/styles.css HTTP/1.1[0m" 304 -
2025-09-23 16:31:23 - api.app - WARNING - not_found:214 - 404 error: http://127.0.0.1:8080/favicon.ico
2025-09-23 16:31:23 - werkzeug - INFO - _log:97 - 127.0.0.1 - - [23/Sep/2025 16:31:23] "[33mGET /favicon.ico HTTP/1.1[0m" 404 -
2025-09-23 16:32:00 - repository.UsersRepository - ERROR - get_connection:70 - Failed to connect to database: invalid connection option "database"

2025-09-23 16:32:00 - repository.UsersRepository - ERROR - execute:117 - db_query_failed
Traceback (most recent call last):
  File "E:\ai-call-copilot\code\api\repositories\base.py", line 62, in get_connection
    conn_params = self._get_connection_params()
                       ^^^^^^^^^^^^^^^^^^^^^^^^^
  File "E:\ai-call-copilot\pvenv\Lib\site-packages\psycopg\connection.py", line 119, in connect
    raise last_ex.with_traceback(None)
psycopg.ProgrammingError: invalid connection option "database"


During handling of the above exception, another exception occurred:

Traceback (most recent call last):
  File "E:\ai-call-copilot\code\api\repositories\base.py", line 78, in execute
    try:
         
  File "E:\ai-call-copilot\code\api\repositories\base.py", line 71, in get_connection
    self.logger.error(f"Failed to connect to database: {e}")
    ^^^^^^^^^^^^^^^^^^^^^^^^^^^^^^^^^^^^^^^^^^^^^^^^^^^^^^^
api.repositories.base.DatabaseError: Database connection failed: invalid connection option "database"

2025-09-23 16:32:00 - api.repositories.users_repo - ERROR - check_email_exists:203 - Error checking email existence: Database connection failed: invalid connection option "database"

2025-09-23 16:32:00 - repository.UsersRepository - ERROR - get_connection:70 - Failed to connect to database: invalid connection option "database"

2025-09-23 16:32:00 - repository.UsersRepository - ERROR - execute:117 - db_query_failed
Traceback (most recent call last):
  File "E:\ai-call-copilot\code\api\repositories\base.py", line 62, in get_connection
    conn_params = self._get_connection_params()
                       ^^^^^^^^^^^^^^^^^^^^^^^^^
  File "E:\ai-call-copilot\pvenv\Lib\site-packages\psycopg\connection.py", line 119, in connect
    raise last_ex.with_traceback(None)
psycopg.ProgrammingError: invalid connection option "database"


During handling of the above exception, another exception occurred:

Traceback (most recent call last):
  File "E:\ai-call-copilot\code\api\repositories\base.py", line 78, in execute
    try:
         
  File "E:\ai-call-copilot\code\api\repositories\base.py", line 71, in get_connection
    self.logger.error(f"Failed to connect to database: {e}")
    ^^^^^^^^^^^^^^^^^^^^^^^^^^^^^^^^^^^^^^^^^^^^^^^^^^^^^^^
api.repositories.base.DatabaseError: Database connection failed: invalid connection option "database"

2025-09-23 16:32:00 - api.repositories.users_repo - ERROR - check_phone_exists:213 - Error checking phone existence: Database connection failed: invalid connection option "database"

2025-09-23 16:32:00 - repository.UsersRepository - ERROR - get_connection:70 - Failed to connect to database: invalid connection option "database"

2025-09-23 16:32:00 - repository.UsersRepository - ERROR - execute:117 - db_query_failed
Traceback (most recent call last):
  File "E:\ai-call-copilot\code\api\repositories\base.py", line 62, in get_connection
    conn_params = self._get_connection_params()
                       ^^^^^^^^^^^^^^^^^^^^^^^^^
  File "E:\ai-call-copilot\pvenv\Lib\site-packages\psycopg\connection.py", line 119, in connect
    raise last_ex.with_traceback(None)
psycopg.ProgrammingError: invalid connection option "database"


During handling of the above exception, another exception occurred:

Traceback (most recent call last):
  File "E:\ai-call-copilot\code\api\repositories\base.py", line 78, in execute
    try:
         
  File "E:\ai-call-copilot\code\api\repositories\base.py", line 71, in get_connection
    self.logger.error(f"Failed to connect to database: {e}")
    ^^^^^^^^^^^^^^^^^^^^^^^^^^^^^^^^^^^^^^^^^^^^^^^^^^^^^^^
api.repositories.base.DatabaseError: Database connection failed: invalid connection option "database"

2025-09-23 16:32:00 - api.repositories.users_repo - ERROR - create_user:73 - Error creating user: Database connection failed: invalid connection option "database"

2025-09-23 16:32:00 - api.controllers.auth_controller - ERROR - register:145 - Registration failed: Database connection failed: invalid connection option "database"

2025-09-23 16:32:00 - werkzeug - INFO - _log:97 - 127.0.0.1 - - [23/Sep/2025 16:32:00] "[35m[1mPOST /api/auth/register HTTP/1.1[0m" 500 -
2025-09-23 16:38:21 - __main__ - INFO - signal_handler:26 - Received signal 2, initiating graceful shutdown...
2025-09-23 16:38:21 - __main__ - ERROR - signal_handler:51 - Error during shutdown: 'DatabaseManager' object has no attribute 'close_all_connections'
